Traceback (most recent call last):
  File "/Users/kvarada/miniconda3/envs/jbook/lib/python3.10/site-packages/jupyter_cache/executors/utils.py", line 58, in single_nb_execution
    executenb(
  File "/Users/kvarada/miniconda3/envs/jbook/lib/python3.10/site-packages/nbclient/client.py", line 1305, in execute
    return NotebookClient(nb=nb, resources=resources, km=km, **kwargs).execute()
  File "/Users/kvarada/miniconda3/envs/jbook/lib/python3.10/site-packages/jupyter_core/utils/__init__.py", line 166, in wrapped
    return loop.run_until_complete(inner)
  File "/Users/kvarada/miniconda3/envs/jbook/lib/python3.10/asyncio/base_events.py", line 649, in run_until_complete
    return future.result()
  File "/Users/kvarada/miniconda3/envs/jbook/lib/python3.10/site-packages/nbclient/client.py", line 705, in async_execute
    await self.async_execute_cell(
  File "/Users/kvarada/miniconda3/envs/jbook/lib/python3.10/site-packages/nbclient/client.py", line 1058, in async_execute_cell
    await self._check_raise_for_error(cell, cell_index, exec_reply)
  File "/Users/kvarada/miniconda3/envs/jbook/lib/python3.10/site-packages/nbclient/client.py", line 914, in _check_raise_for_error
    raise CellExecutionError.from_cell_and_msg(cell, exec_reply_content)
nbclient.exceptions.CellExecutionError: An error occurred while executing the following cell:
------------------
import os, sys
sys.path.append(os.path.join(os.path.abspath(".."), "code"))
from plotting_functions_unsup import *
------------------


[0;31m---------------------------------------------------------------------------[0m
[0;31mModuleNotFoundError[0m                       Traceback (most recent call last)
Cell [0;32mIn[1], line 3[0m
[1;32m      1[0m [38;5;28;01mimport[39;00m [38;5;21;01mos[39;00m[38;5;241m,[39m [38;5;21;01msys[39;00m
[1;32m      2[0m sys[38;5;241m.[39mpath[38;5;241m.[39mappend(os[38;5;241m.[39mpath[38;5;241m.[39mjoin(os[38;5;241m.[39mpath[38;5;241m.[39mabspath([38;5;124m"[39m[38;5;124m..[39m[38;5;124m"[39m), [38;5;124m"[39m[38;5;124mcode[39m[38;5;124m"[39m))
[0;32m----> 3[0m [38;5;28;01mfrom[39;00m [38;5;21;01mplotting_functions_unsup[39;00m [38;5;28;01mimport[39;00m [38;5;241m*[39m

File [0;32m~/CS/2023-24/330/cpsc330-2023W1/lectures/code/plotting_functions_unsup.py:3[0m
[1;32m      1[0m [38;5;28;01mimport[39;00m [38;5;21;01mpandas[39;00m [38;5;28;01mas[39;00m [38;5;21;01mpd[39;00m
[1;32m      2[0m [38;5;28;01mimport[39;00m [38;5;21;01mnumpy[39;00m [38;5;28;01mas[39;00m [38;5;21;01mnp[39;00m
[0;32m----> 3[0m [38;5;28;01mimport[39;00m [38;5;21;01mseaborn[39;00m [38;5;28;01mas[39;00m [38;5;21;01msns[39;00m
[1;32m      4[0m [38;5;28;01mimport[39;00m [38;5;21;01mmatplotlib[39;00m [38;5;28;01mas[39;00m [38;5;21;01mmpl[39;00m
[1;32m      5[0m [38;5;28;01mimport[39;00m [38;5;21;01mmatplotlib[39;00m[38;5;21;01m.[39;00m[38;5;21;01mpyplot[39;00m [38;5;28;01mas[39;00m [38;5;21;01mplt[39;00m

[0;31mModuleNotFoundError[0m: No module named 'seaborn'

