Traceback (most recent call last):
  File "/Users/kvarada/miniconda3/envs/jbook/lib/python3.10/site-packages/jupyter_cache/executors/utils.py", line 58, in single_nb_execution
    executenb(
  File "/Users/kvarada/miniconda3/envs/jbook/lib/python3.10/site-packages/nbclient/client.py", line 1305, in execute
    return NotebookClient(nb=nb, resources=resources, km=km, **kwargs).execute()
  File "/Users/kvarada/miniconda3/envs/jbook/lib/python3.10/site-packages/jupyter_core/utils/__init__.py", line 166, in wrapped
    return loop.run_until_complete(inner)
  File "/Users/kvarada/miniconda3/envs/jbook/lib/python3.10/asyncio/base_events.py", line 649, in run_until_complete
    return future.result()
  File "/Users/kvarada/miniconda3/envs/jbook/lib/python3.10/site-packages/nbclient/client.py", line 705, in async_execute
    await self.async_execute_cell(
  File "/Users/kvarada/miniconda3/envs/jbook/lib/python3.10/site-packages/nbclient/client.py", line 1058, in async_execute_cell
    await self._check_raise_for_error(cell, cell_index, exec_reply)
  File "/Users/kvarada/miniconda3/envs/jbook/lib/python3.10/site-packages/nbclient/client.py", line 914, in _check_raise_for_error
    raise CellExecutionError.from_cell_and_msg(cell, exec_reply_content)
nbclient.exceptions.CellExecutionError: An error occurred while executing the following cell:
------------------
data = pd.DataFrame(data = {"a": list(range(0, 10)),"b": list(range(100, 200, 10))})
profile = ProfileReport(df, title="Profiling Report")
profile.to_widgets()
------------------


[0;31m---------------------------------------------------------------------------[0m
[0;31mNameError[0m                                 Traceback (most recent call last)
Cell [0;32mIn[8], line 2[0m
[1;32m      1[0m data [38;5;241m=[39m pd[38;5;241m.[39mDataFrame(data [38;5;241m=[39m {[38;5;124m"[39m[38;5;124ma[39m[38;5;124m"[39m: [38;5;28mlist[39m([38;5;28mrange[39m([38;5;241m0[39m, [38;5;241m10[39m)),[38;5;124m"[39m[38;5;124mb[39m[38;5;124m"[39m: [38;5;28mlist[39m([38;5;28mrange[39m([38;5;241m100[39m, [38;5;241m200[39m, [38;5;241m10[39m))})
[0;32m----> 2[0m profile [38;5;241m=[39m [43mProfileReport[49m(df, title[38;5;241m=[39m[38;5;124m"[39m[38;5;124mProfiling Report[39m[38;5;124m"[39m)
[1;32m      3[0m profile[38;5;241m.[39mto_widgets()

[0;31mNameError[0m: name 'ProfileReport' is not defined

