Traceback (most recent call last):
  File "/Users/kvarada/miniconda3/envs/jbook/lib/python3.10/site-packages/jupyter_cache/executors/utils.py", line 58, in single_nb_execution
    executenb(
  File "/Users/kvarada/miniconda3/envs/jbook/lib/python3.10/site-packages/nbclient/client.py", line 1305, in execute
    return NotebookClient(nb=nb, resources=resources, km=km, **kwargs).execute()
  File "/Users/kvarada/miniconda3/envs/jbook/lib/python3.10/site-packages/jupyter_core/utils/__init__.py", line 166, in wrapped
    return loop.run_until_complete(inner)
  File "/Users/kvarada/miniconda3/envs/jbook/lib/python3.10/asyncio/base_events.py", line 649, in run_until_complete
    return future.result()
  File "/Users/kvarada/miniconda3/envs/jbook/lib/python3.10/site-packages/nbclient/client.py", line 705, in async_execute
    await self.async_execute_cell(
  File "/Users/kvarada/miniconda3/envs/jbook/lib/python3.10/site-packages/nbclient/client.py", line 1058, in async_execute_cell
    await self._check_raise_for_error(cell, cell_index, exec_reply)
  File "/Users/kvarada/miniconda3/envs/jbook/lib/python3.10/site-packages/nbclient/client.py", line 914, in _check_raise_for_error
    raise CellExecutionError.from_cell_and_msg(cell, exec_reply_content)
nbclient.exceptions.CellExecutionError: An error occurred while executing the following cell:
------------------
select_knn = SelectFromModel(
    KNeighborsClassifier(), 
    threshold="median"
)

pipe_lr_model_based = make_pipeline(
    StandardScaler(), select_knn, LogisticRegression(max_iter=1000)
)

#pd.DataFrame(
#    cross_validate(pipe_lr_model_based, X_train, y_train, return_train_score=True)#
#).mean()
------------------


[0;31m---------------------------------------------------------------------------[0m
[0;31mNameError[0m                                 Traceback (most recent call last)
Cell [0;32mIn[83], line 2[0m
[1;32m      1[0m select_knn [38;5;241m=[39m SelectFromModel(
[0;32m----> 2[0m     [43mKNeighborsClassifier[49m(), 
[1;32m      3[0m     threshold[38;5;241m=[39m[38;5;124m"[39m[38;5;124mmedian[39m[38;5;124m"[39m
[1;32m      4[0m )
[1;32m      6[0m pipe_lr_model_based [38;5;241m=[39m make_pipeline(
[1;32m      7[0m     StandardScaler(), select_knn, LogisticRegression(max_iter[38;5;241m=[39m[38;5;241m1000[39m)
[1;32m      8[0m )
[1;32m     10[0m [38;5;66;03m#pd.DataFrame([39;00m
[1;32m     11[0m [38;5;66;03m#    cross_validate(pipe_lr_model_based, X_train, y_train, return_train_score=True)#[39;00m
[1;32m     12[0m [38;5;66;03m#).mean()[39;00m

[0;31mNameError[0m: name 'KNeighborsClassifier' is not defined

